Workbook
Name OLE_LINK4: 'Operacoes 22.23'!$E$21
Name OLE_LINK4: 'Operacoes 23.24'!$E$22
Name OLE_LINK7: 'Operacoes 22.23'!$E$19
Name OLE_LINK7: 'Operacoes 23.24'!$E$20

Sheet Operacoes 22.23
B2: Tabela - Área plantada por cultura safra 2021/22 x 2022/23 | L2: Table - Planted Area by Crop 2021/22 vs. 2022/23 crop years
B3: Mix de culturas | C3: Área plantada | D3: Área Plantada | E3: Participação | F3: Δ% | L3: Crop Mix | M3: Planted Area | N3: Planted Area | O3: Share | P3: Δ%
C4: 2021/22 | D4: 2022/23 | E4: 2022/23 | M4: 2021/22 | N4: 2022/23 | O4: 2022/23
C5: ------------------ha ------------------ | E5: % | M5: ------------------ha ------------------ | O5: %
B6: Algodão em pluma | C6: 176985 | D6: 162243 | E6: =D6/$D$12 -> 0.24057955 | F6: =D6/C6-1 -> -0.083295195 | L6: Cotton lint | M6: =IF(C6<0,CONCATENATE("(",SUBSTITUTE(SUBSTITUTE(SUBSTITUTE(SUBSTITUTE(TEXT(C6,"#.##0"),",","*"),".",","),"*","."),"-",""),")"),IF(C6=0," -",SUBSTITUTE(SUBSTITUTE(SUBSTITUTE(TEXT(C6,"#.##0"),",","*"),".",","),"*","."))) -> 176,985 | N6: =IF(D6<0,CONCATENATE("(",SUBSTITUTE(SUBSTITUTE(SUBSTITUTE(SUBSTITUTE(TEXT(D6,"#.##0"),",","*"),".",","),"*","."),"-",""),")"),IF(D6=0," -",SUBSTITUTE(SUBSTITUTE(SUBSTITUTE(TEXT(D6,"#.##0"),",","*"),".",","),"*","."))) -> 162,243 | O6: =SUBSTITUTE(TEXT(E6,"0,0%"),",",".") -> 24.1% | P6: =SUBSTITUTE(TEXT(F6,"0,0%"),",",".") -> -8.3%
B7: Algodão em pluma 1ª safra | C7: 86357 | D7: 85823 | E7: =D7/$D$12 -> 0.12726132 | F7: =D7/C7-1 -> -0.0061836331 | L7: Cotton lint 1st crop | M7: =IF(C7<0,CONCATENATE("(",SUBSTITUTE(SUBSTITUTE(SUBSTITUTE(SUBSTITUTE(TEXT(C7,"#.##0"),",","*"),".",","),"*","."),"-",""),")"),IF(C7=0," -",SUBSTITUTE(SUBSTITUTE(SUBSTITUTE(TEXT(C7,"#.##0"),",","*"),".",","),"*","."))) -> 86,357 | N7: =IF(D7<0,CONCATENATE("(",SUBSTITUTE(SUBSTITUTE(SUBSTITUTE(SUBSTITUTE(TEXT(D7,"#.##0"),",","*"),".",","),"*","."),"-",""),")"),IF(D7=0," -",SUBSTITUTE(SUBSTITUTE(SUBSTITUTE(TEXT(D7,"#.##0"),",","*"),".",","),"*","."))) -> 85,823 | O7: =SUBSTITUTE(TEXT(E7,"0,0%"),",",".") -> 12.7% | P7: =SUBSTITUTE(TEXT(F7,"0,0%"),",",".") -> -0.6%
B8: Algodão em pluma 2ª safra | C8: 90628 | D8: 76420 | E8: =D8/$D$12 -> 0.11331823 | F8: =D8/C8-1 -> -0.15677274 | L8: Cotton lint 2nd crop | M8: =IF(C8<0,CONCATENATE("(",SUBSTITUTE(SUBSTITUTE(SUBSTITUTE(SUBSTITUTE(TEXT(C8,"#.##0"),",","*"),".",","),"*","."),"-",""),")"),IF(C8=0," -",SUBSTITUTE(SUBSTITUTE(SUBSTITUTE(TEXT(C8,"#.##0"),",","*"),".",","),"*","."))) -> 90,628 | N8: =IF(D8<0,CONCATENATE("(",SUBSTITUTE(SUBSTITUTE(SUBSTITUTE(SUBSTITUTE(TEXT(D8,"#.##0"),",","*"),".",","),"*","."),"-",""),")"),IF(D8=0," -",SUBSTITUTE(SUBSTITUTE(SUBSTITUTE(TEXT(D8,"#.##0"),",","*"),".",","),"*","."))) -> 76,420 | O8: =SUBSTITUTE(TEXT(E8,"0,0%"),",",".") -> 11.3% | P8: =SUBSTITUTE(TEXT(F8,"0,0%"),",",".") -> -15.7%
B9: Soja (Comercial + Semente) | C9: 334891 | D9: 346941 | E9: =D9/$D$12 -> 0.51445616 | F9: =D9/C9-1 -> 0.035981857 | L9: Soybean (Commercial + Seed) | M9: =IF(C9<0,CONCATENATE("(",SUBSTITUTE(SUBSTITUTE(SUBSTITUTE(SUBSTITUTE(TEXT(C9,"#.##0"),",","*"),".",","),"*","."),"-",""),")"),IF(C9=0," -",SUBSTITUTE(SUBSTITUTE(SUBSTITUTE(TEXT(C9,"#.##0"),",","*"),".",","),"*","."))) -> 334,891 | N9: =IF(D9<0,CONCATENATE("(",SUBSTITUTE(SUBSTITUTE(SUBSTITUTE(SUBSTITUTE(TEXT(D9,"#.##0"),",","*"),".",","),"*","."),"-",""),")"),IF(D9=0," -",SUBSTITUTE(SUBSTITUTE(SUBSTITUTE(TEXT(D9,"#.##0"),",","*"),".",","),"*","."))) -> 346,941 | O9: =SUBSTITUTE(TEXT(E9,"0,0%"),",",".") -> 51.4% | P9: =SUBSTITUTE(TEXT(F9,"0,0%"),",",".") -> 3.6%
B10: Milho 2ª safra | C10: 121633 | D10: 137585 | E10: =D10/$D$12 -> 0.20401581 | F10: =D10/C10-1 -> 0.13114862 | L10: Corn 2nd crop | M10: =IF(C10<0,CONCATENATE("(",SUBSTITUTE(SUBSTITUTE(SUBSTITUTE(SUBSTITUTE(TEXT(C10,"#.##0"),",","*"),".",","),"*","."),"-",""),")"),IF(C10=0," -",SUBSTITUTE(SUBSTITUTE(SUBSTITUTE(TEXT(C10,"#.##0"),",","*"),".",","),"*","."))) -> 121,633 | N10: =IF(D10<0,CONCATENATE("(",SUBSTITUTE(SUBSTITUTE(SUBSTITUTE(SUBSTITUTE(TEXT(D10,"#.##0"),",","*"),".",","),"*","."),"-",""),")"),IF(D10=0," -",SUBSTITUTE(SUBSTITUTE(SUBSTITUTE(TEXT(D10,"#.##0"),",","*"),".",","),"*","."))) -> 137,585 | O10: =SUBSTITUTE(TEXT(E10,"0,0%"),",",".") -> 20.4% | P10: =SUBSTITUTE(TEXT(F10,"0,0%"),",",".") -> 13.1%
B11: Outras culturas (1) | C11: 38437 | D11: 27615 | E11: =D11/$D$12 -> 0.04094848 | F11: =D11/C11-1 -> -0.28155163 | L11: Other Crops (1) | M11: =IF(C11<0,CONCATENATE("(",SUBSTITUTE(SUBSTITUTE(SUBSTITUTE(SUBSTITUTE(TEXT(C11,"#.##0"),",","*"),".",","),"*","."),"-",""),")"),IF(C11=0," -",SUBSTITUTE(SUBSTITUTE(SUBSTITUTE(TEXT(C11,"#.##0"),",","*"),".",","),"*","."))) -> 38,437 | N11: =IF(D11<0,CONCATENATE("(",SUBSTITUTE(SUBSTITUTE(SUBSTITUTE(SUBSTITUTE(TEXT(D11,"#.##0"),",","*"),".",","),"*","."),"-",""),")"),IF(D11=0," -",SUBSTITUTE(SUBSTITUTE(SUBSTITUTE(TEXT(D11,"#.##0"),",","*"),".",","),"*","."))) -> 27,615 | O11: =SUBSTITUTE(TEXT(E11,"0,0%"),",",".") -> 4.1% | P11: =SUBSTITUTE(TEXT(F11,"0,0%"),",",".") -> -28.2%
B12: Área Total | C12: 671946 | D12: 674384 | E12: =D12/$D$12 -> 1 | F12: =D12/C12-1 -> 0.0036282677 | L12: Total Area | M12: =IF(C12<0,CONCATENATE("(",SUBSTITUTE(SUBSTITUTE(SUBSTITUTE(SUBSTITUTE(TEXT(C12,"#.##0"),",","*"),".",","),"*","."),"-",""),")"),IF(C12=0," -",SUBSTITUTE(SUBSTITUTE(SUBSTITUTE(TEXT(C12,"#.##0"),",","*"),".",","),"*","."))) -> 671,946 | N12: =IF(D12<0,CONCATENATE("(",SUBSTITUTE(SUBSTITUTE(SUBSTITUTE(SUBSTITUTE(TEXT(D12,"#.##0"),",","*"),".",","),"*","."),"-",""),")"),IF(D12=0," -",SUBSTITUTE(SUBSTITUTE(SUBSTITUTE(TEXT(D12,"#.##0"),",","*"),".",","),"*","."))) -> 674,384 | O12: =SUBSTITUTE(TEXT(E12,"0,0%"),",",".") -> 100.0% | P12: =SUBSTITUTE(TEXT(F12,"0,0%"),",",".") -> 0.4%
B13: (2) Outras Culturas (Semente de Braquiária 6.314,86 ha, Semente de Estilosantes 716,02 ha, Feijão 1.430,58 ha, Gergelim 2.494,26 ha, Semente de Milheto 8.786,01 ha, Milho 1ª Safra 1.133,88 ha, Milho Semente 667,46 ha, Pecuária 3.962,42 ha, Sorgo 1.041,77 ha e Trigo 1.067,74 ha) total 27.615,00 ha. | L13: (1) Other Crops (Brachiaria Seed 6,314.86 ha, Stylosanthes Seed 716.02 ha, Beans ,1.430.58 ha, Sesame 2.494,26 ha, MIllet Seed 8,786.01 ha, Corn 1st crop 1,133.88 ha, Corn Seed 667.46 ha, Cattle Herd 3,962.42 ha, Sorghum 1,041.77 ha and Wheat 1,067.74 ha) total 27,615 ha.
B15: Tabela - Produtividade Realizada Safra 2022/23 | L15: Table - Achieved Yields 2022/23 crop year
B16: Produtividade (kg/ha) | C16: Safra 2021/22 | D16: Safra 2022/23 | E16: Safra 2022/23 | F16: ∆% | G16: ∆% | L16: Yield (kg/ha) | M16: 2021/22 Crop Year | N16: 2022/23 Crop Year | O16: 2022/23 Crop Year | P16: ∆% | Q16: ∆%
C17: Realizado (a) | D17: Orçado (b) | E17: Realizado (c) | F17: (c) x (a) | G17: (c) x (b) | M17: Achieved (a) | N17: Budget (b) | O17: Forecast(c) | P17: (c) x (a) | Q17: (c) x (b)
B18: Algodão em pluma 1ª safra | C18: 1682 | D18: 1927 | E18: 2000 | F18: 0.189 | G18: 0.038 | L18: Cotton lint 1st crop | M18: =IF(C18<0,CONCATENATE("(",SUBSTITUTE(SUBSTITUTE(SUBSTITUTE(SUBSTITUTE(TEXT(C18,"#.##0"),",","*"),".",","),"*","."),"-",""),")"),IF(C18=0," -",SUBSTITUTE(SUBSTITUTE(SUBSTITUTE(TEXT(C18,"#.##0"),",","*"),".",","),"*","."))) -> 1,682 | N18: =IF(D18<0,CONCATENATE("(",SUBSTITUTE(SUBSTITUTE(SUBSTITUTE(SUBSTITUTE(TEXT(D18,"#.##0"),",","*"),".",","),"*","."),"-",""),")"),IF(D18=0," -",SUBSTITUTE(SUBSTITUTE(SUBSTITUTE(TEXT(D18,"#.##0"),",","*"),".",","),"*","."))) -> 1,927 | O18: =IF(E18<0,CONCATENATE("(",SUBSTITUTE(SUBSTITUTE(SUBSTITUTE(SUBSTITUTE(TEXT(E18,"#.##0"),",","*"),".",","),"*","."),"-",""),")"),IF(E18=0," -",SUBSTITUTE(SUBSTITUTE(SUBSTITUTE(TEXT(E18,"#.##0"),",","*"),".",","),"*","."))) -> 2,000 | P18: =SUBSTITUTE(TEXT(F18,"0,0%"),",",".") -> 18.9% | Q18: =SUBSTITUTE(TEXT(G18,"0,0%"),",",".") -> 3.8%
B19: Algodão em pluma 2ª safra | C19: 1305 | D19: 1839 | E19: 2037 | F19: 0.561 | G19: 0.108 | L19: Cotton lint 2nd crop | M19: =IF(C19<0,CONCATENATE("(",SUBSTITUTE(SUBSTITUTE(SUBSTITUTE(SUBSTITUTE(TEXT(C19,"#.##0"),",","*"),".",","),"*","."),"-",""),")"),IF(C19=0," -",SUBSTITUTE(SUBSTITUTE(SUBSTITUTE(TEXT(C19,"#.##0"),",","*"),".",","),"*","."))) -> 1,305 | N19: =IF(D19<0,CONCATENATE("(",SUBSTITUTE(SUBSTITUTE(SUBSTITUTE(SUBSTITUTE(TEXT(D19,"#.##0"),",","*"),".",","),"*","."),"-",""),")"),IF(D19=0," -",SUBSTITUTE(SUBSTITUTE(SUBSTITUTE(TEXT(D19,"#.##0"),",","*"),".",","),"*","."))) -> 1,839 | O19: =IF(E19<0,CONCATENATE("(",SUBSTITUTE(SUBSTITUTE(SUBSTITUTE(SUBSTITUTE(TEXT(E19,"#.##0"),",","*"),".",","),"*","."),"-",""),")"),IF(E19=0," -",SUBSTITUTE(SUBSTITUTE(SUBSTITUTE(TEXT(E19,"#.##0"),",","*"),".",","),"*","."))) -> 2,037 | P19: =SUBSTITUTE(TEXT(F19,"0,0%"),",",".") -> 56.1% | Q19: =SUBSTITUTE(TEXT(G19,"0,0%"),",",".") -> 10.8%
B20: Caroço de algodão | C20: 1833 | D20: 2372 | E20: 2491 | F20: 0.359 | G20: 0.05 | L20: Cotton seed | M20: =IF(C20<0,CONCATENATE("(",SUBSTITUTE(SUBSTITUTE(SUBSTITUTE(SUBSTITUTE(TEXT(C20,"#.##0"),",","*"),".",","),"*","."),"-",""),")"),IF(C20=0," -",SUBSTITUTE(SUBSTITUTE(SUBSTITUTE(TEXT(C20,"#.##0"),",","*"),".",","),"*","."))) -> 1,833 | N20: =IF(D20<0,CONCATENATE("(",SUBSTITUTE(SUBSTITUTE(SUBSTITUTE(SUBSTITUTE(TEXT(D20,"#.##0"),",","*"),".",","),"*","."),"-",""),")"),IF(D20=0," -",SUBSTITUTE(SUBSTITUTE(SUBSTITUTE(TEXT(D20,"#.##0"),",","*"),".",","),"*","."))) -> 2,372 | O20: =IF(E20<0,CONCATENATE("(",SUBSTITUTE(SUBSTITUTE(SUBSTITUTE(SUBSTITUTE(TEXT(E20,"#.##0"),",","*"),".",","),"*","."),"-",""),")"),IF(E20=0," -",SUBSTITUTE(SUBSTITUTE(SUBSTITUTE(TEXT(E20,"#.##0"),",","*"),".",","),"*","."))) -> 2,491 | P20: =SUBSTITUTE(TEXT(F20,"0,0%"),",",".") -> 35.9% | Q20: =SUBSTITUTE(TEXT(G20,"0,0%"),",",".") -> 5.0%
B21: Soja (Comercial + Semente) | C21: 3974 | D21: 3918 | E21: 3904 | F21: -0.018 | G21: -0.004 | L21: Soybean (Commercial + Seed) | M21: =IF(C21<0,CONCATENATE("(",SUBSTITUTE(SUBSTITUTE(SUBSTITUTE(SUBSTITUTE(TEXT(C21,"#.##0"),",","*"),".",","),"*","."),"-",""),")"),IF(C21=0," -",SUBSTITUTE(SUBSTITUTE(SUBSTITUTE(TEXT(C21,"#.##0"),",","*"),".",","),"*","."))) -> 3,974 | N21: =IF(D21<0,CONCATENATE("(",SUBSTITUTE(SUBSTITUTE(SUBSTITUTE(SUBSTITUTE(TEXT(D21,"#.##0"),",","*"),".",","),"*","."),"-",""),")"),IF(D21=0," -",SUBSTITUTE(SUBSTITUTE(SUBSTITUTE(TEXT(D21,"#.##0"),",","*"),".",","),"*","."))) -> 3,918 | O21: =IF(E21<0,CONCATENATE("(",SUBSTITUTE(SUBSTITUTE(SUBSTITUTE(SUBSTITUTE(TEXT(E21,"#.##0"),",","*"),".",","),"*","."),"-",""),")"),IF(E21=0," -",SUBSTITUTE(SUBSTITUTE(SUBSTITUTE(TEXT(E21,"#.##0"),",","*"),".",","),"*","."))) -> 3,904 | P21: =SUBSTITUTE(TEXT(F21,"0,0%"),",",".") -> -1.8% | Q21: =SUBSTITUTE(TEXT(G21,"0,0%"),",",".") -> -0.4%
B22: Milho 2ª safra | C22: 6303 | D22: 7685 | E22: 7708 | F22: =E22/C22-1 -> 0.22290973 | G22: 0.003 | L22: Corn 2nd crop | M22: =IF(C22<0,CONCATENATE("(",SUBSTITUTE(SUBSTITUTE(SUBSTITUTE(SUBSTITUTE(TEXT(C22,"#.##0"),",","*"),".",","),"*","."),"-",""),")"),IF(C22=0," -",SUBSTITUTE(SUBSTITUTE(SUBSTITUTE(TEXT(C22,"#.##0"),",","*"),".",","),"*","."))) -> 6,303 | N22: =IF(D22<0,CONCATENATE("(",SUBSTITUTE(SUBSTITUTE(SUBSTITUTE(SUBSTITUTE(TEXT(D22,"#.##0"),",","*"),".",","),"*","."),"-",""),")"),IF(D22=0," -",SUBSTITUTE(SUBSTITUTE(SUBSTITUTE(TEXT(D22,"#.##0"),",","*"),".",","),"*","."))) -> 7,685 | O22: =IF(E22<0,CONCATENATE("(",SUBSTITUTE(SUBSTITUTE(SUBSTITUTE(SUBSTITUTE(TEXT(E22,"#.##0"),",","*"),".",","),"*","."),"-",""),")"),IF(E22=0," -",SUBSTITUTE(SUBSTITUTE(SUBSTITUTE(TEXT(E22,"#.##0"),",","*"),".",","),"*","."))) -> 7,708 | P22: =SUBSTITUTE(TEXT(F22,"0,0%"),",",".") -> 22.3% | Q22: =SUBSTITUTE(TEXT(G22,"0,0%"),",",".") -> 0.3%
B25: Tabela - Custos Realizados Safra 2022/23 | L25: Table - Achieved Costs – 2022/23 Crop Year
B26: % | C26: Algodão | D26: Soja | E26: Milho | F26: Média Real. 2022/23 | G26: Média Real. 2021/22 | L26: % | M26: Cotton | N26: Soybean | O26: Corn | P26: Average Ach. 2022/23 | Q26: Average Ach 2021/22
B27: Custos Variáveis | C27: 82.8 | D27: 74.8 | E27: 81.5 | F27: 80.4 | G27: 79.6 | L27: Variable Costs | M27: 82.8 | N27: 74.8 | O27: 81.5 | P27: 80.4 | Q27: 79.6
B28: Sementes | C28: 8.5 | D28: 14.2 | E28: 18.4 | F28: 11.4 | G28: 12.7 | L28: Seeds | M28: 8.5 | N28: 14.2 | O28: 18.4 | P28: 11.4 | Q28: 12.7
B29: Fertilizantes | C29: 24.2 | D29: 15.5 | E29: 34 | F29: 23 | G29: 25.4 | L29: Fertilizers | M29: 24.2 | N29: 15.5 | O29: 34 | P29: 23 | Q29: 25.4
B30: Defensivos | C30: 24.7 | D30: 19.4 | E30: 13.3 | F30: 21.7 | G30: 18.8 | L30: Chemicals | M30: 24.7 | N30: 19.4 | O30: 13.3 | P30: 21.7 | Q30: 18.8
B31: Pulverização Aérea | C31: 1.9 | D31: 1.7 | E31: 1.5 | F31: 1.7 | G31: 1.3 | L31: Air Spraying | M31: 1.9 | N31: 1.7 | O31: 1.5 | P31: 1.7 | Q31: 1.3
B32: Combustíveis e lubrificantes | C32: 3.1 | D32: 5.3 | E32: 3.8 | F32: 3.8 | G32: 4.6 | L32: Fuels and Lubricants | M32: 3.1 | N32: 5.3 | O32: 3.8 | P32: 3.8 | Q32: 4.6
B33: Mão-de-obra | C33: 0.7 | D33: 0.7 | E33: 0.5 | F33: 0.7 | G33: 0.8 | L33: Labor | M33: 0.7 | N33: 0.7 | O33: 0.5 | P33: 0.7 | Q33: 0.8
B34: Beneficiamento | C34: 9 | D34: 3.8 | E34: 2.4 | F34: 6.7 | G34: 4.8 | L34: Ginning | M34: 9.0 | N34: 3.8 | O34: 2.4 | P34: 6.7 | Q34: 4.8
B35: Manutenção de máquinas e implementos | C35: 4.9 | D35: 4.8 | E35: 3.2 | F35: 4.6 | G35: 4.1 | L35: Maintenance | M35: 4.9 | N35: 4.8 | O35: 3.2 | P35: 4.6 | Q35: 4.1
B36: Outros | C36: 5.8 | D36: 9.5 | E36: 4.4 | F36: 6.7 | G36: 7.1 | L36: Others | M36: 5.8 | N36: 9.5 | O36: 4.4 | P36: 6.7 | Q36: 7.1
B37: Custos Fixos | C37: 17.2 | D37: 25.2 | E37: 18.5 | F37: 19.6 | G37: 20.4 | L37: Fixed Costs | M37: 17.2 | N37: 25.2 | O37: 18.5 | P37: 19.6 | Q37: 20.4
B38: Mão-de-obra | C38: 6.2 | D38: 8.1 | E38: 6.1 | F38: 6.7 | G38: 7.2 | L38: Labor | M38: 6.2 | N38: 8.1 | O38: 6.1 | P38: 6.7 | Q38: 7.2
B39: Depreciações e amortizações | C39: 3.6 | D39: 5.8 | E39: 3.8 | F39: 4.3 | G39: 4.4 | L39: Depreciation and amortizations | M39: 3.6 | N39: 5.8 | O39: 3.8 | P39: 4.3 | Q39: 4.4
B40: Depreciação do Direito de Uso -Arrendamentos | C40: 4.7 | D40: 7.6 | E40: 6 | F40: 5.7 | G40: 6.2 | L40: Right-of-Use Depreciation - Leasing | M40: 4.7 | N40: 7.6 | O40: 6 | P40: 5.7 | Q40: 6.2
B41: Outros | C41: 2.7 | D41: 3.6 | E41: 2.6 | F41: 2.9 | G41: 2.6 | L41: Others | M41: 2.7 | N41: 3.6 | O41: 2.6 | P41: 2.9 | Q41: 2.6
B43: Tabela - Custo de produção – Breakdown em R$ por hectare – Safra 2022/23 | L43: Table – Production Cost – Breakdown in % and R$ per hectare – 2022/23 Crop Year
B44: R$/ha | C44: Algodão Real. | D44: Algodão Real. | E44: Soja Real. | F44: Milho Real. | G44: Média Real. | H44: Média Real. | L44: R$/ha | M44: Cotton Achieved | N44: Cotton Achieved | O44: Soybean Achieved | P44: Corn Achieved | Q44: Average Achieved | R44: Average Achieved
C45: 1 ª safra | D45: 2ª safra | F45: 2ª Safra | G45: 2022/23 | H45: 2021/22 | M45: 1st crop | N45: 2nd crop | P45: 2nd crop | Q45: 2022/23 | R45: 2021/22
...

Sheet Operacoes 23.24
B2: Tabela - Área plantada por cultura safra 2022/23 x 2023/24 | L2: Table - Planted Area by Crop 2022/23 vs. 2023/24 crop years
B3: Mix de culturas | C3: Área plantada | D3: Área Plantada | E3: Área Plantada | F3: Participação | G3: Δ% | L3: Crop Mix | M3: Planted Area | N3: Planted Area | O3: Planted Area | P3: Share | Q3: Δ%
C4: 2022/23 | D4: 2023/24 Orçado (a) | E4: 2023/24(1) Forecast (b) | F4: 2023/24 | G4: (b x a) | M4: 2022/23 | N4: 2023/24 Budget (a) | O4: 2023/24(1) Forecast (b) | P4: 2023/24 | Q4: (b x a)
C5: ----------------------------ha ---------------------------- | F5: % | M5: ----------------------------ha ---------------------------- | P5: %
B6: Algodão em pluma | C6: 162243 | D6: 187464 | E6: 188730 | F6: =E6/$E$12 -> 0.28958933 | G6: =E6/D6-1 -> 0.0067532966 | L6: Cotton lint | M6: =IF(C6<0,CONCATENATE("(",SUBSTITUTE(SUBSTITUTE(SUBSTITUTE(SUBSTITUTE(TEXT(C6,"#.##0"),",","*"),".",","),"*","."),"-",""),")"),IF(C6=0," -",SUBSTITUTE(SUBSTITUTE(SUBSTITUTE(TEXT(C6,"#.##0"),",","*"),".",","),"*","."))) -> 162,243 | N6: =IF(D6<0,CONCATENATE("(",SUBSTITUTE(SUBSTITUTE(SUBSTITUTE(SUBSTITUTE(TEXT(D6,"#.##0"),",","*"),".",","),"*","."),"-",""),")"),IF(D6=0," -",SUBSTITUTE(SUBSTITUTE(SUBSTITUTE(TEXT(D6,"#.##0"),",","*"),".",","),"*","."))) -> 187,464 | O6: =IF(E6<0,CONCATENATE("(",SUBSTITUTE(SUBSTITUTE(SUBSTITUTE(SUBSTITUTE(TEXT(E6,"#.##0"),",","*"),".",","),"*","."),"-",""),")"),IF(E6=0," -",SUBSTITUTE(SUBSTITUTE(SUBSTITUTE(TEXT(E6,"#.##0"),",","*"),".",","),"*","."))) -> 188,730 | P6: =SUBSTITUTE(TEXT(F6,"0,0%"),",",".") -> 29.0% | Q6: =SUBSTITUTE(TEXT(G6,"0,0%"),",",".") -> 0.7%
B7: Algodão em pluma 1ª safra | C7: 85823 | D7: 90088 | E7: 106715 | F7: =E7/$E$12 -> 0.16374464 | G7: =E7/D7-1 -> 0.18456398 | L7: Cotton lint 1st crop | M7: =IF(C7<0,CONCATENATE("(",SUBSTITUTE(SUBSTITUTE(SUBSTITUTE(SUBSTITUTE(TEXT(C7,"#.##0"),",","*"),".",","),"*","."),"-",""),")"),IF(C7=0," -",SUBSTITUTE(SUBSTITUTE(SUBSTITUTE(TEXT(C7,"#.##0"),",","*"),".",","),"*","."))) -> 85,823 | N7: =IF(D7<0,CONCATENATE("(",SUBSTITUTE(SUBSTITUTE(SUBSTITUTE(SUBSTITUTE(TEXT(D7,"#.##0"),",","*"),".",","),"*","."),"-",""),")"),IF(D7=0," -",SUBSTITUTE(SUBSTITUTE(SUBSTITUTE(TEXT(D7,"#.##0"),",","*"),".",","),"*","."))) -> 90,088 | O7: =IF(E7<0,CONCATENATE("(",SUBSTITUTE(SUBSTITUTE(SUBSTITUTE(SUBSTITUTE(TEXT(E7,"#.##0"),",","*"),".",","),"*","."),"-",""),")"),IF(E7=0," -",SUBSTITUTE(SUBSTITUTE(SUBSTITUTE(TEXT(E7,"#.##0"),",","*"),".",","),"*","."))) -> 106,715 | P7: =SUBSTITUTE(TEXT(F7,"0,0%"),",",".") -> 16.4% | Q7: =SUBSTITUTE(TEXT(G7,"0,0%"),",",".") -> 18.5%
B8: Algodão em pluma 2ª safra | C8: 76420 | D8: 97376 | E8: 82015 | F8: =E8/$E$12 -> 0.12584469 | G8: =E8/D8-1 -> -0.15774934 | L8: Cotton lint 2nd crop | M8: =IF(C8<0,CONCATENATE("(",SUBSTITUTE(SUBSTITUTE(SUBSTITUTE(SUBSTITUTE(TEXT(C8,"#.##0"),",","*"),".",","),"*","."),"-",""),")"),IF(C8=0," -",SUBSTITUTE(SUBSTITUTE(SUBSTITUTE(TEXT(C8,"#.##0"),",","*"),".",","),"*","."))) -> 76,420 | N8: =IF(D8<0,CONCATENATE("(",SUBSTITUTE(SUBSTITUTE(SUBSTITUTE(SUBSTITUTE(TEXT(D8,"#.##0"),",","*"),".",","),"*","."),"-",""),")"),IF(D8=0," -",SUBSTITUTE(SUBSTITUTE(SUBSTITUTE(TEXT(D8,"#.##0"),",","*"),".",","),"*","."))) -> 97,376 | O8: =IF(E8<0,CONCATENATE("(",SUBSTITUTE(SUBSTITUTE(SUBSTITUTE(SUBSTITUTE(TEXT(E8,"#.##0"),",","*"),".",","),"*","."),"-",""),")"),IF(E8=0," -",SUBSTITUTE(SUBSTITUTE(SUBSTITUTE(TEXT(E8,"#.##0"),",","*"),".",","),"*","."))) -> 82,015 | P8: =SUBSTITUTE(TEXT(F8,"0,0%"),",",".") -> 12.6% | Q8: =SUBSTITUTE(TEXT(G8,"0,0%"),",",".") -> -15.8%
B9: Soja (Comercial + Semente) | C9: 346941 | D9: 336770 | E9: 320009 | F9: =E9/$E$12 -> 0.49102523 | G9: =E9/D9-1 -> -0.049769873 | L9: Soybean (Commercial + Seed) | M9: =IF(C9<0,CONCATENATE("(",SUBSTITUTE(SUBSTITUTE(SUBSTITUTE(SUBSTITUTE(TEXT(C9,"#.##0"),",","*"),".",","),"*","."),"-",""),")"),IF(C9=0," -",SUBSTITUTE(SUBSTITUTE(SUBSTITUTE(TEXT(C9,"#.##0"),",","*"),".",","),"*","."))) -> 346,941 | N9: =IF(D9<0,CONCATENATE("(",SUBSTITUTE(SUBSTITUTE(SUBSTITUTE(SUBSTITUTE(TEXT(D9,"#.##0"),",","*"),".",","),"*","."),"-",""),")"),IF(D9=0," -",SUBSTITUTE(SUBSTITUTE(SUBSTITUTE(TEXT(D9,"#.##0"),",","*"),".",","),"*","."))) -> 336,770 | O9: =IF(E9<0,CONCATENATE("(",SUBSTITUTE(SUBSTITUTE(SUBSTITUTE(SUBSTITUTE(TEXT(E9,"#.##0"),",","*"),".",","),"*","."),"-",""),")"),IF(E9=0," -",SUBSTITUTE(SUBSTITUTE(SUBSTITUTE(TEXT(E9,"#.##0"),",","*"),".",","),"*","."))) -> 320,009 | P9: =SUBSTITUTE(TEXT(F9,"0,0%"),",",".") -> 49.1% | Q9: =SUBSTITUTE(TEXT(G9,"0,0%"),",",".") -> -5.0%
B10: Milho 2ª safra | C10: 137585 | D10: 103436 | E10: 96661 | F10: =E10/$E$12 -> 0.14831767 | G10: =E10/D10-1 -> -0.065499439 | L10: Corn 2nd crop | M10: =IF(C10<0,CONCATENATE("(",SUBSTITUTE(SUBSTITUTE(SUBSTITUTE(SUBSTITUTE(TEXT(C10,"#.##0"),",","*"),".",","),"*","."),"-",""),")"),IF(C10=0," -",SUBSTITUTE(SUBSTITUTE(SUBSTITUTE(TEXT(C10,"#.##0"),",","*"),".",","),"*","."))) -> 137,585 | N10: =IF(D10<0,CONCATENATE("(",SUBSTITUTE(SUBSTITUTE(SUBSTITUTE(SUBSTITUTE(TEXT(D10,"#.##0"),",","*"),".",","),"*","."),"-",""),")"),IF(D10=0," -",SUBSTITUTE(SUBSTITUTE(SUBSTITUTE(TEXT(D10,"#.##0"),",","*"),".",","),"*","."))) -> 103,436 | O10: =IF(E10<0,CONCATENATE("(",SUBSTITUTE(SUBSTITUTE(SUBSTITUTE(SUBSTITUTE(TEXT(E10,"#.##0"),",","*"),".",","),"*","."),"-",""),")"),IF(E10=0," -",SUBSTITUTE(SUBSTITUTE(SUBSTITUTE(TEXT(E10,"#.##0"),",","*"),".",","),"*","."))) -> 96,661 | P10: =SUBSTITUTE(TEXT(F10,"0,0%"),",",".") -> 14.8% | Q10: =SUBSTITUTE(TEXT(G10,"0,0%"),",",".") -> -6.5%
B11: Outras culturas (2) | C11: 27615 | D11: 46733 | E11: 46316 | F11: =E11/$E$12 -> 0.071067766 | G11: =E11/D11-1 -> -0.0089230308 | L11: Other Crops (2) | M11: =IF(C11<0,CONCATENATE("(",SUBSTITUTE(SUBSTITUTE(SUBSTITUTE(SUBSTITUTE(TEXT(C11,"#.##0"),",","*"),".",","),"*","."),"-",""),")"),IF(C11=0," -",SUBSTITUTE(SUBSTITUTE(SUBSTITUTE(TEXT(C11,"#.##0"),",","*"),".",","),"*","."))) -> 27,615 | N11: =IF(D11<0,CONCATENATE("(",SUBSTITUTE(SUBSTITUTE(SUBSTITUTE(SUBSTITUTE(TEXT(D11,"#.##0"),",","*"),".",","),"*","."),"-",""),")"),IF(D11=0," -",SUBSTITUTE(SUBSTITUTE(SUBSTITUTE(TEXT(D11,"#.##0"),",","*"),".",","),"*","."))) -> 46,733 | O11: =IF(E11<0,CONCATENATE("(",SUBSTITUTE(SUBSTITUTE(SUBSTITUTE(SUBSTITUTE(TEXT(E11,"#.##0"),",","*"),".",","),"*","."),"-",""),")"),IF(E11=0," -",SUBSTITUTE(SUBSTITUTE(SUBSTITUTE(TEXT(E11,"#.##0"),",","*"),".",","),"*","."))) -> 46,316 | P11: =SUBSTITUTE(TEXT(F11,"0,0%"),",",".") -> 7.1% | Q11: =SUBSTITUTE(TEXT(G11,"0,0%"),",",".") -> -0.9%
B12: Área Total | C12: 674384 | D12: 674403 | E12: 651716 | F12: =E12/$E$12 -> 1 | G12: =E12/D12-1 -> -0.033640123 | L12: Total Area | M12: =IF(C12<0,CONCATENATE("(",SUBSTITUTE(SUBSTITUTE(SUBSTITUTE(SUBSTITUTE(TEXT(C12,"#.##0"),",","*"),".",","),"*","."),"-",""),")"),IF(C12=0," -",SUBSTITUTE(SUBSTITUTE(SUBSTITUTE(TEXT(C12,"#.##0"),",","*"),".",","),"*","."))) -> 674,384 | N12: =IF(D12<0,CONCATENATE("(",SUBSTITUTE(SUBSTITUTE(SUBSTITUTE(SUBSTITUTE(TEXT(D12,"#.##0"),",","*"),".",","),"*","."),"-",""),")"),IF(D12=0," -",SUBSTITUTE(SUBSTITUTE(SUBSTITUTE(TEXT(D12,"#.##0"),",","*"),".",","),"*","."))) -> 674,403 | O12: =IF(E12<0,CONCATENATE("(",SUBSTITUTE(SUBSTITUTE(SUBSTITUTE(SUBSTITUTE(TEXT(E12,"#.##0"),",","*"),".",","),"*","."),"-",""),")"),IF(E12=0," -",SUBSTITUTE(SUBSTITUTE(SUBSTITUTE(TEXT(E12,"#.##0"),",","*"),".",","),"*","."))) -> 651,716 | P12: =SUBSTITUTE(TEXT(F12,"0,0%"),",",".") -> 100.0% | Q12: =SUBSTITUTE(TEXT(G12,"0,0%"),",",".") -> -3.4%
B13: (1) Fatores climáticos poderão afetar a projeção de área plantada. | L13: (1) Weather factors may affect the planted area forecast.
B14: (2) Outras Culturas (Semente de Braquiária 12.042 ha, Semente de Crotalária 1.859 ha, Feijão 3.482 ha, Gergelim 2.624 ha, Semente de Milheto 6.522 ha, Milho 1ª Safra 266 ha, Milho Semente 767 ha, Semente de Nabo Forrageiro 5.062 ha, Pecuária 3.606 ha, Sorgo 262 ha, Trigo 9.306 ha e Semente de Trigo Mourisco 519 ha) total 46.316 ha. | L14: (2) Other Crops (First-crop corn 266 ha, Corn seed 767 ha, Wheat 9,306 ha, Mung bean 3,482 ha, Livestock 3,606 ha, Sorghum 262 ha, Sesame 2,624 ha, Brachiaria seed 12,042 ha, Buckwheat 519 ha, Pearl millet seed 6,522 ha, Crotalaria 1,859 ha, Forage Radish Seed 5,062 ha) Total 46,316 hectares.
B16: Tabela - Produtividade Orçada Safra 2023/24 | L16: Table - Projected Yields 2023/24 crop year
B17: Produtividade (kg/ha) | C17: Safra 2022/23 | D17: Safra 2023/24 | E17: Safra 2023/24 | F17: ∆% | G17: ∆% | L17: Yield (kg/ha) | M17: 2022/23 Crop Year | N17: 2023/24 Crop Year | O17: 2023/24 Crop Year | P17: ∆% | Q17: ∆%
C18: Realizado (a) | D18: Orçado (b) | E18: Forecast (c) | F18: (c) x (a) | G18: (c) x (b) | M18: Achieved (a) | N18: Budget (b) | O18: Forecast(c) | P18: (c) x (a) | Q18: (c) x (b)
B19: Algodão em pluma 1ª safra | C19: 2000 | D19: 2020 | E19: 2020 | F19: =E19/C19-1 -> 0.01 | G19: =E19/D19-1 -> 0 | L19: Cotton lint 1st crop | M19: =IF(C19<0,CONCATENATE("(",SUBSTITUTE(SUBSTITUTE(SUBSTITUTE(SUBSTITUTE(TEXT(C19,"#.##0"),",","*"),".",","),"*","."),"-",""),")"),IF(C19=0," -",SUBSTITUTE(SUBSTITUTE(SUBSTITUTE(TEXT(C19,"#.##0"),",","*"),".",","),"*","."))) -> 2,000 | N19: =IF(D19<0,CONCATENATE("(",SUBSTITUTE(SUBSTITUTE(SUBSTITUTE(SUBSTITUTE(TEXT(D19,"#.##0"),",","*"),".",","),"*","."),"-",""),")"),IF(D19=0," -",SUBSTITUTE(SUBSTITUTE(SUBSTITUTE(TEXT(D19,"#.##0"),",","*"),".",","),"*","."))) -> 2,020 | O19: =IF(E19<0,CONCATENATE("(",SUBSTITUTE(SUBSTITUTE(SUBSTITUTE(SUBSTITUTE(TEXT(E19,"#.##0"),",","*"),".",","),"*","."),"-",""),")"),IF(E19=0," -",SUBSTITUTE(SUBSTITUTE(SUBSTITUTE(TEXT(E19,"#.##0"),",","*"),".",","),"*","."))) -> 2,020 | P19: =SUBSTITUTE(TEXT(F19,"0,0%"),",",".") -> 1.0% | Q19: =SUBSTITUTE(TEXT(G19,"0,0%"),",",".") -> 0.0%
B20: Algodão em pluma 2ª safra | C20: 2037 | D20: 1869 | E20: 1869 | F20: =E20/C20-1 -> -0.082474227 | G20: =E20/D20-1 -> 0 | L20: Cotton lint 2nd crop | M20: =IF(C20<0,CONCATENATE("(",SUBSTITUTE(SUBSTITUTE(SUBSTITUTE(SUBSTITUTE(TEXT(C20,"#.##0"),",","*"),".",","),"*","."),"-",""),")"),IF(C20=0," -",SUBSTITUTE(SUBSTITUTE(SUBSTITUTE(TEXT(C20,"#.##0"),",","*"),".",","),"*","."))) -> 2,037 | N20: =IF(D20<0,CONCATENATE("(",SUBSTITUTE(SUBSTITUTE(SUBSTITUTE(SUBSTITUTE(TEXT(D20,"#.##0"),",","*"),".",","),"*","."),"-",""),")"),IF(D20=0," -",SUBSTITUTE(SUBSTITUTE(SUBSTITUTE(TEXT(D20,"#.##0"),",","*"),".",","),"*","."))) -> 1,869 | O20: =IF(E20<0,CONCATENATE("(",SUBSTITUTE(SUBSTITUTE(SUBSTITUTE(SUBSTITUTE(TEXT(E20,"#.##0"),",","*"),".",","),"*","."),"-",""),")"),IF(E20=0," -",SUBSTITUTE(SUBSTITUTE(SUBSTITUTE(TEXT(E20,"#.##0"),",","*"),".",","),"*","."))) -> 1,869 | P20: =SUBSTITUTE(TEXT(F20,"0,0%"),",",".") -> -8.2% | Q20: =SUBSTITUTE(TEXT(G20,"0,0%"),",",".") -> 0.0%
B21: Caroço de algodão | C21: 2491 | D21: 2410 | E21: 2410 | F21: =E21/C21-1 -> -0.032517061 | G21: =E21/D21-1 -> 0 | L21: Cotton seed | M21: =IF(C21<0,CONCATENATE("(",SUBSTITUTE(SUBSTITUTE(SUBSTITUTE(SUBSTITUTE(TEXT(C21,"#.##0"),",","*"),".",","),"*","."),"-",""),")"),IF(C21=0," -",SUBSTITUTE(SUBSTITUTE(SUBSTITUTE(TEXT(C21,"#.##0"),",","*"),".",","),"*","."))) -> 2,491 | N21: =IF(D21<0,CONCATENATE("(",SUBSTITUTE(SUBSTITUTE(SUBSTITUTE(SUBSTITUTE(TEXT(D21,"#.##0"),",","*"),".",","),"*","."),"-",""),")"),IF(D21=0," -",SUBSTITUTE(SUBSTITUTE(SUBSTITUTE(TEXT(D21,"#.##0"),",","*"),".",","),"*","."))) -> 2,410 | O21: =IF(E21<0,CONCATENATE("(",SUBSTITUTE(SUBSTITUTE(SUBSTITUTE(SUBSTITUTE(TEXT(E21,"#.##0"),",","*"),".",","),"*","."),"-",""),")"),IF(E21=0," -",SUBSTITUTE(SUBSTITUTE(SUBSTITUTE(TEXT(E21,"#.##0"),",","*"),".",","),"*","."))) -> 2,410 | P21: =SUBSTITUTE(TEXT(F21,"0,0%"),",",".") -> -3.3% | Q21: =SUBSTITUTE(TEXT(G21,"0,0%"),",",".") -> 0.0%
B22: Soja (Comercial + Semente) | C22: 3904 | D22: 3948 | E22: 3432 | F22: =E22/C22-1 -> -0.12090164 | G22: =E22/D22-1 -> -0.13069909 | L22: Soybean (Commercial + Seed) | M22: =IF(C22<0,CONCATENATE("(",SUBSTITUTE(SUBSTITUTE(SUBSTITUTE(SUBSTITUTE(TEXT(C22,"#.##0"),",","*"),".",","),"*","."),"-",""),")"),IF(C22=0," -",SUBSTITUTE(SUBSTITUTE(SUBSTITUTE(TEXT(C22,"#.##0"),",","*"),".",","),"*","."))) -> 3,904 | N22: =IF(D22<0,CONCATENATE("(",SUBSTITUTE(SUBSTITUTE(SUBSTITUTE(SUBSTITUTE(TEXT(D22,"#.##0"),",","*"),".",","),"*","."),"-",""),")"),IF(D22=0," -",SUBSTITUTE(SUBSTITUTE(SUBSTITUTE(TEXT(D22,"#.##0"),",","*"),".",","),"*","."))) -> 3,948 | O22: =IF(E22<0,CONCATENATE("(",SUBSTITUTE(SUBSTITUTE(SUBSTITUTE(SUBSTITUTE(TEXT(E22,"#.##0"),",","*"),".",","),"*","."),"-",""),")"),IF(E22=0," -",SUBSTITUTE(SUBSTITUTE(SUBSTITUTE(TEXT(E22,"#.##0"),",","*"),".",","),"*","."))) -> 3,432 | P22: =SUBSTITUTE(TEXT(F22,"0,0%"),",",".") -> -12.1% | Q22: =SUBSTITUTE(TEXT(G22,"0,0%"),",",".") -> -13.1%
B23: Milho 2ª safra | C23: 7708 | D23: 7580 | E23: 7580 | F23: =E23/C23-1 -> -0.016606124 | G23: =E23/D23-1 -> 0 | L23: Corn 2nd crop | M23: =IF(C23<0,CONCATENATE("(",SUBSTITUTE(SUBSTITUTE(SUBSTITUTE(SUBSTITUTE(TEXT(C23,"#.##0"),",","*"),".",","),"*","."),"-",""),")"),IF(C23=0," -",SUBSTITUTE(SUBSTITUTE(SUBSTITUTE(TEXT(C23,"#.##0"),",","*"),".",","),"*","."))) -> 7,708 | N23: =IF(D23<0,CONCATENATE("(",SUBSTITUTE(SUBSTITUTE(SUBSTITUTE(SUBSTITUTE(TEXT(D23,"#.##0"),",","*"),".",","),"*","."),"-",""),")"),IF(D23=0," -",SUBSTITUTE(SUBSTITUTE(SUBSTITUTE(TEXT(D23,"#.##0"),",","*"),".",","),"*","."))) -> 7,580 | O23: =IF(E23<0,CONCATENATE("(",SUBSTITUTE(SUBSTITUTE(SUBSTITUTE(SUBSTITUTE(TEXT(E23,"#.##0"),",","*"),".",","),"*","."),"-",""),")"),IF(E23=0," -",SUBSTITUTE(SUBSTITUTE(SUBSTITUTE(TEXT(E23,"#.##0"),",","*"),".",","),"*","."))) -> 7,580 | P23: =SUBSTITUTE(TEXT(F23,"0,0%"),",",".") -> -1.7% | Q23: =SUBSTITUTE(TEXT(G23,"0,0%"),",",".") -> 0.0%
B26: Tabela - Custos Orçadas Safra 2023/24 | L26: Table - Budgeted Costs – 2023/24 Crop Year
B27: % | C27: Algodão | D27: Soja | E27: Milho | F27: Média Orç. 2023/24 | G27: Média Orç. 2022/23 | L27: % | M27: Cotton | N27: Soybean | O27: Corn | P27: Average Budg. 2023/24 | Q27: Average Budg. 2022/23
B28: Custos Variáveis | C28: 79.6 | D28: 74.8 | E28: 80 | F28: 77.8 | G28: 79.8 | L28: Variable Costs | M28: =IF(C28<0,CONCATENATE("(",SUBSTITUTE(SUBSTITUTE(SUBSTITUTE(SUBSTITUTE(TEXT(C28,"#.##0,00"),",","*"),".",","),"*","."),"-",""),")"),IF(C28=0," -",SUBSTITUTE(SUBSTITUTE(SUBSTITUTE(TEXT(C28,"#.##0,0"),",","*"),".",","),"*","."))) -> 79.6 | N28: =IF(D28<0,CONCATENATE("(",SUBSTITUTE(SUBSTITUTE(SUBSTITUTE(SUBSTITUTE(TEXT(D28,"#.##0,00"),",","*"),".",","),"*","."),"-",""),")"),IF(D28=0," -",SUBSTITUTE(SUBSTITUTE(SUBSTITUTE(TEXT(D28,"#.##0,0"),",","*"),".",","),"*","."))) -> 74.8 | O28: =IF(E28<0,CONCATENATE("(",SUBSTITUTE(SUBSTITUTE(SUBSTITUTE(SUBSTITUTE(TEXT(E28,"#.##0,00"),",","*"),".",","),"*","."),"-",""),")"),IF(E28=0," -",SUBSTITUTE(SUBSTITUTE(SUBSTITUTE(TEXT(E28,"#.##0,0"),",","*"),".",","),"*","."))) -> 80.0 | P28: =IF(F28<0,CONCATENATE("(",SUBSTITUTE(SUBSTITUTE(SUBSTITUTE(SUBSTITUTE(TEXT(F28,"#.##0,00"),",","*"),".",","),"*","."),"-",""),")"),IF(F28=0," -",SUBSTITUTE(SUBSTITUTE(SUBSTITUTE(TEXT(F28,"#.##0,0"),",","*"),".",","),"*","."))) -> 77.8 | Q28: =IF(G28<0,CONCATENATE("(",SUBSTITUTE(SUBSTITUTE(SUBSTITUTE(SUBSTITUTE(TEXT(G28,"#.##0,00"),",","*"),".",","),"*","."),"-",""),")"),IF(G28=0," -",SUBSTITUTE(SUBSTITUTE(SUBSTITUTE(TEXT(G28,"#.##0,0"),",","*"),".",","),"*","."))) -> 79.8
B29: Sementes | C29: 10.1 | D29: 15.2 | E29: 21.5 | F29: 13.2 | G29: 11.1 | L29: Seeds | M29: =IF(C29<0,CONCATENATE("(",SUBSTITUTE(SUBSTITUTE(SUBSTITUTE(SUBSTITUTE(TEXT(C29,"#.##0,00"),",","*"),".",","),"*","."),"-",""),")"),IF(C29=0," -",SUBSTITUTE(SUBSTITUTE(SUBSTITUTE(TEXT(C29,"#.##0,0"),",","*"),".",","),"*","."))) -> 10.1 | N29: =IF(D29<0,CONCATENATE("(",SUBSTITUTE(SUBSTITUTE(SUBSTITUTE(SUBSTITUTE(TEXT(D29,"#.##0,00"),",","*"),".",","),"*","."),"-",""),")"),IF(D29=0," -",SUBSTITUTE(SUBSTITUTE(SUBSTITUTE(TEXT(D29,"#.##0,0"),",","*"),".",","),"*","."))) -> 15.2 | O29: =IF(E29<0,CONCATENATE("(",SUBSTITUTE(SUBSTITUTE(SUBSTITUTE(SUBSTITUTE(TEXT(E29,"#.##0,00"),",","*"),".",","),"*","."),"-",""),")"),IF(E29=0," -",SUBSTITUTE(SUBSTITUTE(SUBSTITUTE(TEXT(E29,"#.##0,0"),",","*"),".",","),"*","."))) -> 21.5 | P29: =IF(F29<0,CONCATENATE("(",SUBSTITUTE(SUBSTITUTE(SUBSTITUTE(SUBSTITUTE(TEXT(F29,"#.##0,00"),",","*"),".",","),"*","."),"-",""),")"),IF(F29=0," -",SUBSTITUTE(SUBSTITUTE(SUBSTITUTE(TEXT(F29,"#.##0,0"),",","*"),".",","),"*","."))) -> 13.2 | Q29: =IF(G29<0,CONCATENATE("(",SUBSTITUTE(SUBSTITUTE(SUBSTITUTE(SUBSTITUTE(TEXT(G29,"#.##0,00"),",","*"),".",","),"*","."),"-",""),")"),IF(G29=0," -",SUBSTITUTE(SUBSTITUTE(SUBSTITUTE(TEXT(G29,"#.##0,0"),",","*"),".",","),"*","."))) -> 11.1
B30: Fertilizantes | C30: 21.1 | D30: 18.7 | E30: 32 | F30: 21.3 | G30: 23.2 | L30: Fertilizers | M30: =IF(C30<0,CONCATENATE("(",SUBSTITUTE(SUBSTITUTE(SUBSTITUTE(SUBSTITUTE(TEXT(C30,"#.##0,00"),",","*"),".",","),"*","."),"-",""),")"),IF(C30=0," -",SUBSTITUTE(SUBSTITUTE(SUBSTITUTE(TEXT(C30,"#.##0,0"),",","*"),".",","),"*","."))) -> 21.1 | N30: =IF(D30<0,CONCATENATE("(",SUBSTITUTE(SUBSTITUTE(SUBSTITUTE(SUBSTITUTE(TEXT(D30,"#.##0,00"),",","*"),".",","),"*","."),"-",""),")"),IF(D30=0," -",SUBSTITUTE(SUBSTITUTE(SUBSTITUTE(TEXT(D30,"#.##0,0"),",","*"),".",","),"*","."))) -> 18.7 | O30: =IF(E30<0,CONCATENATE("(",SUBSTITUTE(SUBSTITUTE(SUBSTITUTE(SUBSTITUTE(TEXT(E30,"#.##0,00"),",","*"),".",","),"*","."),"-",""),")"),IF(E30=0," -",SUBSTITUTE(SUBSTITUTE(SUBSTITUTE(TEXT(E30,"#.##0,0"),",","*"),".",","),"*","."))) -> 32.0 | P30: =IF(F30<0,CONCATENATE("(",SUBSTITUTE(SUBSTITUTE(SUBSTITUTE(SUBSTITUTE(TEXT(F30,"#.##0,00"),",","*"),".",","),"*","."),"-",""),")"),IF(F30=0," -",SUBSTITUTE(SUBSTITUTE(SUBSTITUTE(TEXT(F30,"#.##0,0"),",","*"),".",","),"*","."))) -> 21.3 | Q30: =IF(G30<0,CONCATENATE("(",SUBSTITUTE(SUBSTITUTE(SUBSTITUTE(SUBSTITUTE(TEXT(G30,"#.##0,00"),",","*"),".",","),"*","."),"-",""),")"),IF(G30=0," -",SUBSTITUTE(SUBSTITUTE(SUBSTITUTE(TEXT(G30,"#.##0,0"),",","*"),".",","),"*","."))) -> 23.2
B31: Defensivos | C31: 20.4 | D31: 16.8 | E31: 10.9 | F31: 18.1 | G31: 20.6 | L31: Chemicals | M31: =IF(C31<0,CONCATENATE("(",SUBSTITUTE(SUBSTITUTE(SUBSTITUTE(SUBSTITUTE(TEXT(C31,"#.##0,00"),",","*"),".",","),"*","."),"-",""),")"),IF(C31=0," -",SUBSTITUTE(SUBSTITUTE(SUBSTITUTE(TEXT(C31,"#.##0,0"),",","*"),".",","),"*","."))) -> 20.4 | N31: =IF(D31<0,CONCATENATE("(",SUBSTITUTE(SUBSTITUTE(SUBSTITUTE(SUBSTITUTE(TEXT(D31,"#.##0,00"),",","*"),".",","),"*","."),"-",""),")"),IF(D31=0," -",SUBSTITUTE(SUBSTITUTE(SUBSTITUTE(TEXT(D31,"#.##0,0"),",","*"),".",","),"*","."))) -> 16.8 | O31: =IF(E31<0,CONCATENATE("(",SUBSTITUTE(SUBSTITUTE(SUBSTITUTE(SUBSTITUTE(TEXT(E31,"#.##0,00"),",","*"),".",","),"*","."),"-",""),")"),IF(E31=0," -",SUBSTITUTE(SUBSTITUTE(SUBSTITUTE(TEXT(E31,"#.##0,0"),",","*"),".",","),"*","."))) -> 10.9 | P31: =IF(F31<0,CONCATENATE("(",SUBSTITUTE(SUBSTITUTE(SUBSTITUTE(SUBSTITUTE(TEXT(F31,"#.##0,00"),",","*"),".",","),"*","."),"-",""),")"),IF(F31=0," -",SUBSTITUTE(SUBSTITUTE(SUBSTITUTE(TEXT(F31,"#.##0,0"),",","*"),".",","),"*","."))) -> 18.1 | Q31: =IF(G31<0,CONCATENATE("(",SUBSTITUTE(SUBSTITUTE(SUBSTITUTE(SUBSTITUTE(TEXT(G31,"#.##0,00"),",","*"),".",","),"*","."),"-",""),")"),IF(G31=0," -",SUBSTITUTE(SUBSTITUTE(SUBSTITUTE(TEXT(G31,"#.##0,0"),",","*"),".",","),"*","."))) -> 20.6
B32: Pulverização Aérea | C32: 2.3 | D32: 1.4 | E32: 1.6 | F32: 1.9 | G32: 1.6 | L32: Air Spraying | M32: =IF(C32<0,CONCATENATE("(",SUBSTITUTE(SUBSTITUTE(SUBSTITUTE(SUBSTITUTE(TEXT(C32,"#.##0,00"),",","*"),".",","),"*","."),"-",""),")"),IF(C32=0," -",SUBSTITUTE(SUBSTITUTE(SUBSTITUTE(TEXT(C32,"#.##0,0"),",","*"),".",","),"*","."))) -> 2.3 | N32: =IF(D32<0,CONCATENATE("(",SUBSTITUTE(SUBSTITUTE(SUBSTITUTE(SUBSTITUTE(TEXT(D32,"#.##0,00"),",","*"),".",","),"*","."),"-",""),")"),IF(D32=0," -",SUBSTITUTE(SUBSTITUTE(SUBSTITUTE(TEXT(D32,"#.##0,0"),",","*"),".",","),"*","."))) -> 1.4 | O32: =IF(E32<0,CONCATENATE("(",SUBSTITUTE(SUBSTITUTE(SUBSTITUTE(SUBSTITUTE(TEXT(E32,"#.##0,00"),",","*"),".",","),"*","."),"-",""),")"),IF(E32=0," -",SUBSTITUTE(SUBSTITUTE(SUBSTITUTE(TEXT(E32,"#.##0,0"),",","*"),".",","),"*","."))) -> 1.6 | P32: =IF(F32<0,CONCATENATE("(",SUBSTITUTE(SUBSTITUTE(SUBSTITUTE(SUBSTITUTE(TEXT(F32,"#.##0,00"),",","*"),".",","),"*","."),"-",""),")"),IF(F32=0," -",SUBSTITUTE(SUBSTITUTE(SUBSTITUTE(TEXT(F32,"#.##0,0"),",","*"),".",","),"*","."))) -> 1.9 | Q32: =IF(G32<0,CONCATENATE("(",SUBSTITUTE(SUBSTITUTE(SUBSTITUTE(SUBSTITUTE(TEXT(G32,"#.##0,00"),",","*"),".",","),"*","."),"-",""),")"),IF(G32=0," -",SUBSTITUTE(SUBSTITUTE(SUBSTITUTE(TEXT(G32,"#.##0,0"),",","*"),".",","),"*","."))) -> 1.6
B33: Combustíveis e lubrificantes | C33: 3.4 | D33: 3.5 | E33: 3.6 | F33: 3.5 | G33: 4.3 | L33: Fuels and Lubricants | M33: =IF(C33<0,CONCATENATE("(",SUBSTITUTE(SUBSTITUTE(SUBSTITUTE(SUBSTITUTE(TEXT(C33,"#.##0,00"),",","*"),".",","),"*","."),"-",""),")"),IF(C33=0," -",SUBSTITUTE(SUBSTITUTE(SUBSTITUTE(TEXT(C33,"#.##0,0"),",","*"),".",","),"*","."))) -> 3.4 | N33: =IF(D33<0,CONCATENATE("(",SUBSTITUTE(SUBSTITUTE(SUBSTITUTE(SUBSTITUTE(TEXT(D33,"#.##0,00"),",","*"),".",","),"*","."),"-",""),")"),IF(D33=0," -",SUBSTITUTE(SUBSTITUTE(SUBSTITUTE(TEXT(D33,"#.##0,0"),",","*"),".",","),"*","."))) -> 3.5 | O33: =IF(E33<0,CONCATENATE("(",SUBSTITUTE(SUBSTITUTE(SUBSTITUTE(SUBSTITUTE(TEXT(E33,"#.##0,00"),",","*"),".",","),"*","."),"-",""),")"),IF(E33=0," -",SUBSTITUTE(SUBSTITUTE(SUBSTITUTE(TEXT(E33,"#.##0,0"),",","*"),".",","),"*","."))) -> 3.6 | P33: =IF(F33<0,CONCATENATE("(",SUBSTITUTE(SUBSTITUTE(SUBSTITUTE(SUBSTITUTE(TEXT(F33,"#.##0,00"),",","*"),".",","),"*","."),"-",""),")"),IF(F33=0," -",SUBSTITUTE(SUBSTITUTE(SUBSTITUTE(TEXT(F33,"#.##0,0"),",","*"),".",","),"*","."))) -> 3.5 | Q33: =IF(G33<0,CONCATENATE("(",SUBSTITUTE(SUBSTITUTE(SUBSTITUTE(SUBSTITUTE(TEXT(G33,"#.##0,00"),",","*"),".",","),"*","."),"-",""),")"),IF(G33=0," -",SUBSTITUTE(SUBSTITUTE(SUBSTITUTE(TEXT(G33,"#.##0,0"),",","*"),".",","),"*","."))) -> 4.3
B34: Mão-de-obra | C34: 0.9 | D34: 0.7 | E34: 0.6 | F34: 0.8 | G34: 0.6 | L34: Labor | M34: =IF(C34<0,CONCATENATE("(",SUBSTITUTE(SUBSTITUTE(SUBSTITUTE(SUBSTITUTE(TEXT(C34,"#.##0,00"),",","*"),".",","),"*","."),"-",""),")"),IF(C34=0," -",SUBSTITUTE(SUBSTITUTE(SUBSTITUTE(TEXT(C34,"#.##0,0"),",","*"),".",","),"*","."))) -> 0.9 | N34: =IF(D34<0,CONCATENATE("(",SUBSTITUTE(SUBSTITUTE(SUBSTITUTE(SUBSTITUTE(TEXT(D34,"#.##0,00"),",","*"),".",","),"*","."),"-",""),")"),IF(D34=0," -",SUBSTITUTE(SUBSTITUTE(SUBSTITUTE(TEXT(D34,"#.##0,0"),",","*"),".",","),"*","."))) -> 0.7 | O34: =IF(E34<0,CONCATENATE("(",SUBSTITUTE(SUBSTITUTE(SUBSTITUTE(SUBSTITUTE(TEXT(E34,"#.##0,00"),",","*"),".",","),"*","."),"-",""),")"),IF(E34=0," -",SUBSTITUTE(SUBSTITUTE(SUBSTITUTE(TEXT(E34,"#.##0,0"),",","*"),".",","),"*","."))) -> 0.6 | P34: =IF(F34<0,CONCATENATE("(",SUBSTITUTE(SUBSTITUTE(SUBSTITUTE(SUBSTITUTE(TEXT(F34,"#.##0,00"),",","*"),".",","),"*","."),"-",""),")"),IF(F34=0," -",SUBSTITUTE(SUBSTITUTE(SUBSTITUTE(TEXT(F34,"#.##0,0"),",","*"),".",","),"*","."))) -> 0.8 | Q34: =IF(G34<0,CONCATENATE("(",SUBSTITUTE(SUBSTITUTE(SUBSTITUTE(SUBSTITUTE(TEXT(G34,"#.##0,00"),",","*"),".",","),"*","."),"-",""),")"),IF(G34=0," -",SUBSTITUTE(SUBSTITUTE(SUBSTITUTE(TEXT(G34,"#.##0,0"),",","*"),".",","),"*","."))) -> 0.6
B35: Beneficiamento | C35: 9.7 | D35: 3 | E35: 2.4 | F35: 6.4 | G35: 6.3 | L35: Ginning | M35: =IF(C35<0,CONCATENATE("(",SUBSTITUTE(SUBSTITUTE(SUBSTITUTE(SUBSTITUTE(TEXT(C35,"#.##0,00"),",","*"),".",","),"*","."),"-",""),")"),IF(C35=0," -",SUBSTITUTE(SUBSTITUTE(SUBSTITUTE(TEXT(C35,"#.##0,0"),",","*"),".",","),"*","."))) -> 9.7 | N35: =IF(D35<0,CONCATENATE("(",SUBSTITUTE(SUBSTITUTE(SUBSTITUTE(SUBSTITUTE(TEXT(D35,"#.##0,00"),",","*"),".",","),"*","."),"-",""),")"),IF(D35=0," -",SUBSTITUTE(SUBSTITUTE(SUBSTITUTE(TEXT(D35,"#.##0,0"),",","*"),".",","),"*","."))) -> 3.0 | O35: =IF(E35<0,CONCATENATE("(",SUBSTITUTE(SUBSTITUTE(SUBSTITUTE(SUBSTITUTE(TEXT(E35,"#.##0,00"),",","*"),".",","),"*","."),"-",""),")"),IF(E35=0," -",SUBSTITUTE(SUBSTITUTE(SUBSTITUTE(TEXT(E35,"#.##0,0"),",","*"),".",","),"*","."))) -> 2.4 | P35: =IF(F35<0,CONCATENATE("(",SUBSTITUTE(SUBSTITUTE(SUBSTITUTE(SUBSTITUTE(TEXT(F35,"#.##0,00"),",","*"),".",","),"*","."),"-",""),")"),IF(F35=0," -",SUBSTITUTE(SUBSTITUTE(SUBSTITUTE(TEXT(F35,"#.##0,0"),",","*"),".",","),"*","."))) -> 6.4 | Q35: =IF(G35<0,CONCATENATE("(",SUBSTITUTE(SUBSTITUTE(SUBSTITUTE(SUBSTITUTE(TEXT(G35,"#.##0,00"),",","*"),".",","),"*","."),"-",""),")"),IF(G35=0," -",SUBSTITUTE(SUBSTITUTE(SUBSTITUTE(TEXT(G35,"#.##0,0"),",","*"),".",","),"*","."))) -> 6.3
B36: Manutenção de máquinas e implementos | C36: 4.3 | D36: 4.1 | E36: 3.3 | F36: 4.1 | G36: 4 | L36: Maintenance | M36: =IF(C36<0,CONCATENATE("(",SUBSTITUTE(SUBSTITUTE(SUBSTITUTE(SUBSTITUTE(TEXT(C36,"#.##0,00"),",","*"),".",","),"*","."),"-",""),")"),IF(C36=0," -",SUBSTITUTE(SUBSTITUTE(SUBSTITUTE(TEXT(C36,"#.##0,0"),",","*"),".",","),"*","."))) -> 4.3 | N36: =IF(D36<0,CONCATENATE("(",SUBSTITUTE(SUBSTITUTE(SUBSTITUTE(SUBSTITUTE(TEXT(D36,"#.##0,00"),",","*"),".",","),"*","."),"-",""),")"),IF(D36=0," -",SUBSTITUTE(SUBSTITUTE(SUBSTITUTE(TEXT(D36,"#.##0,0"),",","*"),".",","),"*","."))) -> 4.1 | O36: =IF(E36<0,CONCATENATE("(",SUBSTITUTE(SUBSTITUTE(SUBSTITUTE(SUBSTITUTE(TEXT(E36,"#.##0,00"),",","*"),".",","),"*","."),"-",""),")"),IF(E36=0," -",SUBSTITUTE(SUBSTITUTE(SUBSTITUTE(TEXT(E36,"#.##0,0"),",","*"),".",","),"*","."))) -> 3.3 | P36: =IF(F36<0,CONCATENATE("(",SUBSTITUTE(SUBSTITUTE(SUBSTITUTE(SUBSTITUTE(TEXT(F36,"#.##0,00"),",","*"),".",","),"*","."),"-",""),")"),IF(F36=0," -",SUBSTITUTE(SUBSTITUTE(SUBSTITUTE(TEXT(F36,"#.##0,0"),",","*"),".",","),"*","."))) -> 4.1 | Q36: =IF(G36<0,CONCATENATE("(",SUBSTITUTE(SUBSTITUTE(SUBSTITUTE(SUBSTITUTE(TEXT(G36,"#.##0,00"),",","*"),".",","),"*","."),"-",""),")"),IF(G36=0," -",SUBSTITUTE(SUBSTITUTE(SUBSTITUTE(TEXT(G36,"#.##0,0"),",","*"),".",","),"*","."))) -> 4.0
B37: Outros | C37: 7.4 | D37: 11.4 | E37: 4 | F37: 8.5 | G37: 8.1 | L37: Others | M37: =IF(C37<0,CONCATENATE("(",SUBSTITUTE(SUBSTITUTE(SUBSTITUTE(SUBSTITUTE(TEXT(C37,"#.##0,00"),",","*"),".",","),"*","."),"-",""),")"),IF(C37=0," -",SUBSTITUTE(SUBSTITUTE(SUBSTITUTE(TEXT(C37,"#.##0,0"),",","*"),".",","),"*","."))) -> 7.4 | N37: =IF(D37<0,CONCATENATE("(",SUBSTITUTE(SUBSTITUTE(SUBSTITUTE(SUBSTITUTE(TEXT(D37,"#.##0,00"),",","*"),".",","),"*","."),"-",""),")"),IF(D37=0," -",SUBSTITUTE(SUBSTITUTE(SUBSTITUTE(TEXT(D37,"#.##0,0"),",","*"),".",","),"*","."))) -> 11.4 | O37: =IF(E37<0,CONCATENATE("(",SUBSTITUTE(SUBSTITUTE(SUBSTITUTE(SUBSTITUTE(TEXT(E37,"#.##0,00"),",","*"),".",","),"*","."),"-",""),")"),IF(E37=0," -",SUBSTITUTE(SUBSTITUTE(SUBSTITUTE(TEXT(E37,"#.##0,0"),",","*"),".",","),"*","."))) -> 4.0 | P37: =IF(F37<0,CONCATENATE("(",SUBSTITUTE(SUBSTITUTE(SUBSTITUTE(SUBSTITUTE(TEXT(F37,"#.##0,00"),",","*"),".",","),"*","."),"-",""),")"),IF(F37=0," -",SUBSTITUTE(SUBSTITUTE(SUBSTITUTE(TEXT(F37,"#.##0,0"),",","*"),".",","),"*","."))) -> 8.5 | Q37: =IF(G37<0,CONCATENATE("(",SUBSTITUTE(SUBSTITUTE(SUBSTITUTE(SUBSTITUTE(TEXT(G37,"#.##0,00"),",","*"),".",","),"*","."),"-",""),")"),IF(G37=0," -",SUBSTITUTE(SUBSTITUTE(SUBSTITUTE(TEXT(G37,"#.##0,0"),",","*"),".",","),"*","."))) -> 8.1
B38: Custos Fixos | C38: 20.4 | D38: 25.2 | E38: 20 | F38: 22.2 | G38: 20.2 | L38: Fixed Costs | M38: =IF(C38<0,CONCATENATE("(",SUBSTITUTE(SUBSTITUTE(SUBSTITUTE(SUBSTITUTE(TEXT(C38,"#.##0,00"),",","*"),".",","),"*","."),"-",""),")"),IF(C38=0," -",SUBSTITUTE(SUBSTITUTE(SUBSTITUTE(TEXT(C38,"#.##0,0"),",","*"),".",","),"*","."))) -> 20.4 | N38: =IF(D38<0,CONCATENATE("(",SUBSTITUTE(SUBSTITUTE(SUBSTITUTE(SUBSTITUTE(TEXT(D38,"#.##0,00"),",","*"),".",","),"*","."),"-",""),")"),IF(D38=0," -",SUBSTITUTE(SUBSTITUTE(SUBSTITUTE(TEXT(D38,"#.##0,0"),",","*"),".",","),"*","."))) -> 25.2 | O38: =IF(E38<0,CONCATENATE("(",SUBSTITUTE(SUBSTITUTE(SUBSTITUTE(SUBSTITUTE(TEXT(E38,"#.##0,00"),",","*"),".",","),"*","."),"-",""),")"),IF(E38=0," -",SUBSTITUTE(SUBSTITUTE(SUBSTITUTE(TEXT(E38,"#.##0,0"),",","*"),".",","),"*","."))) -> 20.0 | P38: =IF(F38<0,CONCATENATE("(",SUBSTITUTE(SUBSTITUTE(SUBSTITUTE(SUBSTITUTE(TEXT(F38,"#.##0,00"),",","*"),".",","),"*","."),"-",""),")"),IF(F38=0," -",SUBSTITUTE(SUBSTITUTE(SUBSTITUTE(TEXT(F38,"#.##0,0"),",","*"),".",","),"*","."))) -> 22.2 | Q38: =IF(G38<0,CONCATENATE("(",SUBSTITUTE(SUBSTITUTE(SUBSTITUTE(SUBSTITUTE(TEXT(G38,"#.##0,00"),",","*"),".",","),"*","."),"-",""),")"),IF(G38=0," -",SUBSTITUTE(SUBSTITUTE(SUBSTITUTE(TEXT(G38,"#.##0,0"),",","*"),".",","),"*","."))) -> 20.2
B39: Mão-de-obra | C39: 7.2 | D39: 8.1 | E39: 6.4 | F39: 7.4 | G39: 6.6 | L39: Labor | M39: =IF(C39<0,CONCATENATE("(",SUBSTITUTE(SUBSTITUTE(SUBSTITUTE(SUBSTITUTE(TEXT(C39,"#.##0,00"),",","*"),".",","),"*","."),"-",""),")"),IF(C39=0," -",SUBSTITUTE(SUBSTITUTE(SUBSTITUTE(TEXT(C39,"#.##0,0"),",","*"),".",","),"*","."))) -> 7.2 | N39: =IF(D39<0,CONCATENATE("(",SUBSTITUTE(SUBSTITUTE(SUBSTITUTE(SUBSTITUTE(TEXT(D39,"#.##0,00"),",","*"),".",","),"*","."),"-",""),")"),IF(D39=0," -",SUBSTITUTE(SUBSTITUTE(SUBSTITUTE(TEXT(D39,"#.##0,0"),",","*"),".",","),"*","."))) -> 8.1 | O39: =IF(E39<0,CONCATENATE("(",SUBSTITUTE(SUBSTITUTE(SUBSTITUTE(SUBSTITUTE(TEXT(E39,"#.##0,00"),",","*"),".",","),"*","."),"-",""),")"),IF(E39=0," -",SUBSTITUTE(SUBSTITUTE(SUBSTITUTE(TEXT(E39,"#.##0,0"),",","*"),".",","),"*","."))) -> 6.4 | P39: =IF(F39<0,CONCATENATE("(",SUBSTITUTE(SUBSTITUTE(SUBSTITUTE(SUBSTITUTE(TEXT(F39,"#.##0,00"),",","*"),".",","),"*","."),"-",""),")"),IF(F39=0," -",SUBSTITUTE(SUBSTITUTE(SUBSTITUTE(TEXT(F39,"#.##0,0"),",","*"),".",","),"*","."))) -> 7.4 | Q39: =IF(G39<0,CONCATENATE("(",SUBSTITUTE(SUBSTITUTE(SUBSTITUTE(SUBSTITUTE(TEXT(G39,"#.##0,00"),",","*"),".",","),"*","."),"-",""),")"),IF(G39=0," -",SUBSTITUTE(SUBSTITUTE(SUBSTITUTE(TEXT(G39,"#.##0,0"),",","*"),".",","),"*","."))) -> 6.6
... B42: Outros | C42: 2.8 | D42: 3.4 | E42: 2.7 | F42: 3.1 | G42: 2.8 | L42: Others | M42: =IF(C42<0,CONCATENATE("(",SUBSTITUTE(SUBSTITUTE(SUBSTITUTE(SUBSTITUTE(TEXT(C42,"#.##0,00"),",","*"),".",","),"*","."),"-",""),")"),IF(C42=0," -",SUBSTITUTE(SUBSTITUTE(SUBSTITUTE(TEXT(C42,"#.##0,0"),",","*"),".",","),"*","."))) -> 2.8 | N42: =IF(D42<0,CONCATENATE("(",SUBSTITUTE(SUBSTITUTE(SUBSTITUTE(SUBSTITUTE(TEXT(D42,"#.##0,00"),",","*"),".",","),"*","."),"-",""),")"),IF(D42=0," -",SUBSTITUTE(SUBSTITUTE(SUBSTITUTE(TEXT(D42,"#.##0,0"),",","*"),".",","),"*","."))) -> 3.4 | O42: =IF(E42<0,CONCATENATE("(",SUBSTITUTE(SUBSTITUTE(SUBSTITUTE(SUBSTITUTE(TEXT(E42,"#.##0,00"),",","*"),".",","),"*","."),"-",""),")"),IF(E42=0," -",SUBSTITUTE(SUBSTITUTE(SUBSTITUTE(TEXT(E42,"#.##0,0"),",","*"),".",","),"*","."))) -> 2.7 | P42: =IF(F42<0,CONCATENATE("(",SUBSTITUTE(SUBSTITUTE(SUBSTITUTE(SUBSTITUTE(TEXT(F42,"#.##0,00"),",","*"),".",","),"*","."),"-",""),")"),IF(F42=0," -",SUBSTITUTE(SUBSTITUTE(SUBSTITUTE(TEXT(F42,"#.##0,0"),",","*"),".",","),"*","."))) -> 3.1 | Q42: =IF(G42<0,CONCATENATE("(",SUBSTITUTE(SUBSTITUTE(SUBSTITUTE(SUBSTITUTE(TEXT(G42,"#.##0,00"),",","*"),".",","),"*","."),"-",""),")"),IF(G42=0," -",SUBSTITUTE(SUBSTITUTE(SUBSTITUTE(TEXT(G42,"#.##0,0"),",","*"),".",","),"*","."))) -> 2.8
B44: Tabela - Custo de produção – Breakdown em R$ por hectare – Safra 2023/24 | L44: Table – Production Cost – Breakdown in % and R$ per hectare – 2023/24 Crop Year
B45: R$/ha | C45: Algodão Orçado | D45: Algodão Orçado | E45: Soja Orçado | F45: Milho Orçado | G45: Média Orçado | H45: Média Orçado | L45: R$/ha | M45: Cotton Butdget | N45: Cotton Butdget | O45: Soybean Budget | P45: Corn Budget | Q45: Average Budget | R45: Average Budget
C46: 1 ª safra | D46: 2ª safra | F46: 2ª Safra | G46: 2023/24 | H46: 2022/23 | M46: 1st crop | N46: 2nd crop | P46: 2nd crop | Q46: 2023/24 | R46: 2022/23
B47: Custos Variáveis | C47: =SUM(C48:C56) -> 12069.748 | D47: =SUM(D48:D56) -> 10886.892 | E47: =SUM(E48:E56) -> 3906.804 | F47: =SUM(F48:F56) -> 3888.733 | G47: =SUM(G48:G56) -> 5583.706 | H47: =SUM(H48:H56) -> 6372.03 | L47: Variable Costs | M47: =IF(C47<0,CONCATENATE("(",SUBSTITUTE(SUBSTITUTE(SUBSTITUTE(SUBSTITUTE(TEXT(C47,"#.##0"),",","*"),".",","),"*","."),"-",""),")"),IF(C47=0," -",SUBSTITUTE(SUBSTITUTE(SUBSTITUTE(TEXT(C47,"#.##0"),",","*"),".",","),"*","."))) -> 12,070 | N47: =IF(D47<0,CONCATENATE("(",SUBSTITUTE(SUBSTITUTE(SUBSTITUTE(SUBSTITUTE(TEXT(D47,"#.##0"),",","*"),".",","),"*","."),"-",""),")"),IF(D47=0," -",SUBSTITUTE(SUBSTITUTE(SUBSTITUTE(TEXT(D47,"#.##0"),",","*"),".",","),"*","."))) -> 10,887 | O47: =IF(E47<0,CONCATENATE("(",SUBSTITUTE(SUBSTITUTE(SUBSTITUTE(SUBSTITUTE(TEXT(E47,"#.##0"),",","*"),".",","),"*","."),"-",""),")"),IF(E47=0," -",SUBSTITUTE(SUBSTITUTE(SUBSTITUTE(TEXT(E47,"#.##0"),",","*"),".",","),"*","."))) -> 3,907 | P47: =IF(F47<0,CONCATENATE("(",SUBSTITUTE(SUBSTITUTE(SUBSTITUTE(SUBSTITUTE(TEXT(F47,"#.##0"),",","*"),".",","),"*","."),"-",""),")"),IF(F47=0," -",SUBSTITUTE(SUBSTITUTE(SUBSTITUTE(TEXT(F47,"#.##0"),",","*"),".",","),"*","."))) -> 3,889 | Q47: =IF(G47<0,CONCATENATE("(",SUBSTITUTE(SUBSTITUTE(SUBSTITUTE(SUBSTITUTE(TEXT(G47,"#.##0"),",","*"),".",","),"*","."),"-",""),")"),IF(G47=0," -",SUBSTITUTE(SUBSTITUTE(SUBSTITUTE(TEXT(G47,"#.##0"),",","*"),".",","),"*","."))) -> 5,584 | R47: =IF(H47<0,CONCATENATE("(",SUBSTITUTE(SUBSTITUTE(SUBSTITUTE(SUBSTITUTE(TEXT(H47,"#.##0"),",","*"),".",","),"*","."),"-",""),")"),IF(H47=0," -",SUBSTITUTE(SUBSTITUTE(SUBSTITUTE(TEXT(H47,"#.##0"),",","*"),".",","),"*","."))) -> 6,372
...
